Workbook

Sheet Cooking Model No.s
A1: building final energy by service and fuel
A2: scenario | B2: region | C2: input | D2: sector | E2: 1990 | F2: 2005 | G2: 2010 | H2: 2015 | I2: 2020 | J2: 2025 | K2: 2030 | L2: 2035 | M2: 2040 | N2: 2045 | O2: 2050 | P2: 2055 | Q2: 2060 | R2: 2065 | S2: 2070
A3: BAU_Final,date=2025-4-8T18:20:06+06:030 | B3: AN | C3: delivered biomass | D3: comm others | E3: 7.787e-05 | F3: 9.92201e-05 | G3: 0.000106165 | H3: 6.69915e-07 | I3: 1.64578e-07 | J3: 1.3573e-07 | K3: 1.13863e-07 | L3: 9.86822e-08 | M3: 6.84276e-08 | N3: 3.76505e-08 | O3: 0 | P3: 0 | Q3: 0 | R3: 0 | S3: 0
A4: BAU_Final,date=2025-4-8T18:20:06+06:030 | B4: AN | C4: delivered coal | D4: comm others | E4: 6.07766e-05 | F4: 5.34108e-05 | G4: 7.84738e-05 | H4: 3.07782e-07 | I4: 0.000266448 | J4: 0 | K4: 0 | L4: 0 | M4: 0 | N4: 0 | O4: 0 | P4: 0 | Q4: 0 | R4: 0 | S4: 0
A5: BAU_Final,date=2025-4-8T18:20:06+06:030 | B5: AN | C5: delivered coal | D5: resid rural apploth | E5: 5.852e-05 | F5: 5.14077e-05 | G5: 2.00254e-07 | H5: 1.77275e-07 | I5: 0 | J5: 7.31228e-05 | K5: 0 | L5: 0 | M5: 0 | N5: 0 | O5: 0 | P5: 0 | Q5: 0 | R5: 0 | S5: 0
A6: BAU_Final,date=2025-4-8T18:20:06+06:030 | B6: AN | C6: delivered coal | D6: resid rural cooking | E6: 5.86878e-05 | F6: 5.14901e-05 | G6: 1.99674e-07 | H6: 3.16812e-06 | I6: 2.86562e-08 | J6: 8.5881e-08 | K6: 0 | L6: 0 | M6: 0 | N6: 0 | O6: 0 | P6: 0 | Q6: 0 | R6: 0 | S6: 0
A7: BAU_Final,date=2025-4-8T18:20:06+06:030 | B7: AN | C7: delivered coal | D7: resid rural space heating | E7: 5.80608e-06 | F7: 4.99221e-06 | G7: 0 | H7: 4.9029e-06 | I7: 5.11227e-07 | J7: 6.81246e-08 | K7: 0 | L7: 0 | M7: 0 | N7: 0 | O7: 0 | P7: 0 | Q7: 0 | R7: 0 | S7: 0
A8: BAU_Final,date=2025-4-8T18:20:06+06:030 | B8: AN | C8: delivered coal | D8: resid urban apploth | E8: 0 | F8: 0 | G8: 0 | H8: 1.05228e-05 | I8: 0 | J8: 0 | K8: 0 | L8: 0 | M8: 0 | N8: 0 | O8: 0 | P8: 0 | Q8: 0 | R8: 0 | S8: 0
A9: BAU_Final,date=2025-4-8T18:20:06+06:030 | B9: AN | C9: delivered coal | D9: resid urban cooking | E9: 0 | F9: 0 | G9: 0 | H9: 5.22194e-07 | I9: 0 | J9: 0 | K9: 0 | L9: 0 | M9: 0 | N9: 0 | O9: 0 | P9: 0 | Q9: 0 | R9: 0 | S9: 0
A10: BAU_Final,date=2025-4-8T18:20:06+06:030 | B10: AN | C10: delivered gas | D10: comm cooking | E10: 0 | F10: 0 | G10: 0 | H10: 0 | I10: 1.67196e-05 | J10: 3.19334e-05 | K10: 5.81331e-05 | L10: 8.713551e-05 | M10: 0.0001195588 | N10: 0.00014585104 | O10: 0.00017457179 | P10: 0.00020467571 | Q10: 0.00023564128 | R10: 0.00026639797 | S10: 0.00029774194
A11: BAU_Final,date=2025-4-8T18:20:06+06:030 | B11: AN | C11: delivered gas | D11: resid urban cooking | E11: 0 | F11: 0 | G11: 0 | H11: 0 | I11: 2.07011e-06 | J11: 3.363918e-05 | K11: 0.00014290297 | L11: 0.00023639136 | M11: 0.00031876604 | N11: 0.0003729372 | O11: 0.00042353129 | P11: 0.0004660575 | Q11: 0.0005128212 | R11: 0.0005609141 | S11: 0.0006117564
A12: BAU_Final,date=2025-4-8T18:20:06+06:030 | B12: AN | C12: elect_td_com | D12: comm cooking | E12: 1.04863e-05 | F12: 3.2422e-05 | G12: 8.50873e-06 | H12: 9.70944e-06 | I12: 8.45657e-06 | J12: 1.3660692e-05 | K12: 1.522204e-05 | L12: 1.7015056e-05 | M12: 1.9003287e-05 | N12: 2.1091728e-05 | O12: 2.4063888e-05 | P12: 2.7563253e-05 | Q12: 3.1463682e-05 | R12: 3.5543503e-05 | S12: 3.9765171e-05
A13: BAU_Final,date=2025-4-8T18:20:06+06:030 | B13: AN | C13: elect_td_com | D13: comm hvac | E13: 0.000192385 | F13: 0.0005985 | G13: 0.000156885 | H13: 7.50029e-05 | I13: 5.5763e-05 | J13: 0.0001495333 | K13: 0.0001969428 | L13: 0.000254867 | M13: 0.0003019608 | N13: 0.0003548429 | O13: 0.00040859357 | P13: 0.0004609904 | Q13: 0.0005120562 | R13: 0.0005619553 | S13: 0.0006083047
... A1210: BAU_Final,date=2025-4-8T18:20:06+06:030 | B1210: WB | C1210: traditional biomass | D1210: resid rural cooking | E1210: 0.241664 | F1210: 0.283145 | G1210: 0.300943 | H1210: 0.281824 | I1210: 0.461028 | J1210: 0.141494 | K1210: 0.105297 | L1210: 0.0859071 | M1210: 0.0592161 | N1210: 0.0273646 | O1210: 0 | P1210: 0 | Q1210: 0 | R1210: 0 | S1210: 0

Sheet PNGCylinderHH
A1: region | B1: sector | C1: 2010 | D1: 2015 | E1: 2020 | F1: 2025 | G1: 2030 | H1: 2035 | I1: 2040 | J1: 2045 | K1: 2050 | L1: 2055 | M1: 2060 | N1: 2065 | O1: 2070 | R1: region | S1: sector | T1: 2010 | U1: 2015 | V1: 2020 | W1: 2025 | X1: 2030 | Y1: 2035 | Z1: 2040 | AA1: 2045 | AB1: 2050 | AC1: 2055 | AD1: 2060 | AE1: 2065 | AF1: 2070
A2: AN | B2: resid urban cooking | C2: 0 | D2: 0 | E2: 2.07011e-06 | F2: 3.363918e-05 | G2: 0.00014290297 | H2: 0.00023639136 | I2: 0.00031876604 | J2: 0.0003729372 | K2: 0.00042353129 | L2: 0.0004660575 | M2: 0.0005128212 | N2: 0.0005609141 | O2: 0.0006117564 | R2: AN | S2: resid urban cooking | T2: =(((C2*10^9)/0.037679)/14.2)/(C42*1000) -> 0 | U2: =(((D2*10^9)/0.037679)/14.2)/(D42*1000) -> 0 | V2: =(((E2*10^9)/0.037679)/14.2)/(E42*1000) -> 0.022494548 | W2: =(((F2*10^9)/0.037679)/14.2)/(F42*1000) -> 0.33472318 | X2: =(((G2*10^9)/0.037679)/14.2)/(G42*1000) -> 1.3067542 | Y2: =(((H2*10^9)/0.037679)/14.2)/(H42*1000) -> 1.9969017 | Z2: =(((I2*10^9)/0.037679)/14.2)/(I42*1000) -> 2.4750135 | AA2: =(((J2*10^9)/0.037679)/14.2)/(J42*1000) -> 2.7536549 | ... AF2: =(((O2*10^9)/0.037679)/14.2)/(O42*1000) -> 3.6403655
A3: AP | B3: resid urban cooking | C3: 0 | D3: 6.97741e-05 | E3: 0.0005622408 | F3: 0.0061893338 | G3: 0.011344222 | H3: 0.016798315 | I3: 0.023296071 | J3: 0.028353429 | K3: 0.033204131 | L3: 0.037122741 | M3: 0.040920052 | N3: 0.0447022 | O3: 0.04851553 | R3: AP | S3: resid urban cooking | T3: =(((C3*10^9)/0.037679)/14.2)/(C43*1000) -> 0 | U3: =(((D3*10^9)/0.037679)/14.2)/(D43*1000) -> 0.0078516882 | V3: =(((E3*10^9)/0.037679)/14.2)/(E43*1000) -> 0.056441899 | W3: =(((F3*10^9)/0.037679)/14.2)/(F43*1000) -> 0.56228768 | X3: =(((G3*10^9)/0.037679)/14.2)/(G43*1000) -> 0.9433562 | Y3: =(((H3*10^9)/0.037679)/14.2)/(H43*1000) -> 1.2877984 | Z3: =(((I3*10^9)/0.037679)/14.2)/(I43*1000) -> 1.6561617 | AA3: =(((J3*10^9)/0.037679)/14.2)/(J43*1000) -> 1.8918476 | ... AF3: =(((O3*10^9)/0.037679)/14.2)/(O43*1000) -> 3.0047104
A4: AR | B4: resid urban cooking | C4: 0 | D4: 0 | E4: 2.06818e-06 | F4: 0.0001809568 | G4: 0.00036565948 | H4: 0.00056788509 | I4: 0.0007928963 | J4: 0.00098704538 | K4: 0.0011742669 | L4: 0.0013196045 | M4: 0.0014704868 | N4: 0.0016176163 | O4: 0.0017630902 | R4: AR | S4: resid urban cooking | T4: =(((C4*10^9)/0.037679)/14.2)/(C44*1000) -> 0 | U4: =(((D4*10^9)/0.037679)/14.2)/(D44*1000) -> 0 | V4: =(((E4*10^9)/0.037679)/14.2)/(E44*1000) -> 0.010014132 | W4: =(((F4*10^9)/0.037679)/14.2)/(F44*1000) -> 0.80144688 | X4: =(((G4*10^9)/0.037679)/14.2)/(G44*1000) -> 1.4921884 | Y4: =(((H4*10^9)/0.037679)/14.2)/(H44*1000) -> 2.1417449 | Z4: =(((I4*10^9)/0.037679)/14.2)/(I44*1000) -> 2.7563418 | AA4: =(((J4*10^9)/0.037679)/14.2)/(J44*1000) -> 3.2676726 | ... AF4: =(((O4*10^9)/0.037679)/14.2)/(O44*1000) -> 5.2294246
A5: AS | B5: resid urban cooking | C5: 4.10001e-06 | D5: 3.16474e-06 | E5: 4.435769e-05 | F5: 0.0033545294 | G5: 0.0068164567 | H5: 0.010479986 | I5: 0.015888209 | J5: 0.019852016 | K5: 0.023933157 | L5: 0.027465416 | M5: 0.031276817 | N5: 0.035263359 | O5: 0.03943932 | R5: AS | S5: resid urban cooking | T5: =(((C5*10^9)/0.037679)/14.2)/(C45*1000) -> 0.0017419803 | U5: =(((D5*10^9)/0.037679)/14.2)/(D45*1000) -> 0.0012123262 | V5: =(((E5*10^9)/0.037679)/14.2)/(E45*1000) -> 0.015444317 | W5: =(((F5*10^9)/0.037679)/14.2)/(F45*1000) -> 1.072103 | X5: =(((G5*10^9)/0.037679)/14.2)/(G45*1000) -> 2.0164681 | Y5: =(((H5*10^9)/0.037679)/14.2)/(H45*1000) -> 2.896662 | Z5: =(((I5*10^9)/0.037679)/14.2)/(I45*1000) -> 3.8876291 | AA5: =(((J5*10^9)/0.037679)/14.2)/(J45*1000) -> 4.369806 | ... AF5: =(((O5*10^9)/0.037679)/14.2)/(O45*1000) -> 5.9773916
A6: BR | B6: resid urban cooking | C6: 0 | D6: 0 | E6: 0 | F6: 0.00514562 | G6: 0.02111993 | H6: 0.02718117 | I6: 0.03532734 | J6: 0.04097859 | K6: 0.046672244 | L6: 0.05391726 | M6: 0.06180977 | N6: 0.07182258 | O6: 0.08253833 | R6: BR | S6: resid urban cooking | T6: =(((C6*10^9)/0.037679)/14.2)/(C46*1000) -> 0 | U6: =(((D6*10^9)/0.037679)/14.2)/(D46*1000) -> 0 | V6: =(((E6*10^9)/0.037679)/14.2)/(E46*1000) -> 0 | W6: =(((F6*10^9)/0.037679)/14.2)/(F46*1000) -> 0.58096109 | X6: =(((G6*10^9)/0.037679)/14.2)/(G46*1000) -> 2.1689884 | Y6: =(((H6*10^9)/0.037679)/14.2)/(H46*1000) -> 2.5734236 | Z6: =(((I6*10^9)/0.037679)/14.2)/(I46*1000) -> 3.067055 | AA6: =(((J6*10^9)/0.037679)/14.2)/(J46*1000) -> 3.2341495 | ... AF6: =(((O6*10^9)/0.037679)/14.2)/(O46*1000) -> 4.1087315
A7: CG | B7: resid urban cooking | C7: 0 | D7: 0 | E7: 0 | F7: 0 | G7: 0.00704773 | H7: 0.00981538 | I7: 0.01333172 | J7: 0.01597027 | K7: 0.01874191 | L7: 0.021338404 | M7: 0.024028478 | N7: 0.026732884 | O7: 0.029390788 | R7: CG | S7: resid urban cooking | T7: =(((C7*10^9)/0.037679)/14.2)/(C47*1000) -> 0 | U7: =(((D7*10^9)/0.037679)/14.2)/(D47*1000) -> 0 | V7: =(((E7*10^9)/0.037679)/14.2)/(E47*1000) -> 0 | W7: =(((F7*10^9)/0.037679)/14.2)/(F47*1000) -> 0 | X7: =(((G7*10^9)/0.037679)/14.2)/(G47*1000) -> 1.3568498 | Y7: =(((H7*10^9)/0.037679)/14.2)/(H47*1000) -> 1.720926 | Z7: =(((I7*10^9)/0.037679)/14.2)/(I47*1000) -> 2.1485493 | AA7: =(((J7*10^9)/0.037679)/14.2)/(J47*1000) -> 2.4891083 | ... AF7: =(((O7*10^9)/0.037679)/14.2)/(O47*1000) -> 4.1547613
A8: CH | B8: resid urban cooking | C8: 0 | D8: 0 | E8: 2.85187e-07 | F8: 0.00012680063 | G8: 0.00025516125 | H8: 0.00035567519 | I8: 0.00046229024 | J8: 0.00053878716 | K8: 0.0006077014 | L8: 0.0006687227 | M8: 0.0007325578 | N8: 0.0007962973 | O8: 0.0008610899 | R8: CH | S8: resid urban cooking | T8: =(((C8*10^9)/0.037679)/14.2)/(C48*1000) -> 0 | U8: =(((D8*10^9)/0.037679)/14.2)/(D48*1000) -> 0 | V8: =(((E8*10^9)/0.037679)/14.2)/(E48*1000) -> 0.00044569718 | W8: =(((F8*10^9)/0.037679)/14.2)/(F48*1000) -> 0.18893912 | X8: =(((G8*10^9)/0.037679)/14.2)/(G48*1000) -> 0.36192098 | Y8: =(((H8*10^9)/0.037679)/14.2)/(H48*1000) -> 0.48100019 | Z8: =(((I8*10^9)/0.037679)/14.2)/(I48*1000) -> 0.59777667 | AA8: =(((J8*10^9)/0.037679)/14.2)/(J48*1000) -> 0.65666355 | ... AF8: =(((O8*10^9)/0.037679)/14.2)/(O48*1000) -> 0.89864264
A9: DD | B9: resid urban cooking | C9: 0 | D9: 0 | E9: 0 | F9: 1.70268e-06 | G9: 0.00012178044 | H9: 0.00032301543 | I9: 0.00053847114 | J9: 0.00070690415 | K9: 0.00082855925 | L9: 0.0009281998 | M9: 0.0009900633 | N9: 0.001045399 | O9: 0.0010986727 | R9: DD | S9: resid urban cooking | T9: =(((C9*10^9)/0.037679)/14.2)/(C49*1000) -> 0 | U9: =(((D9*10^9)/0.037679)/14.2)/(D49*1000) -> 0 | V9: =(((E9*10^9)/0.037679)/14.2)/(E49*1000) -> 0 | W9: =(((F9*10^9)/0.037679)/14.2)/(F49*1000) -> 0.0046389662 | X9: =(((G9*10^9)/0.037679)/14.2)/(G49*1000) -> 0.21536159 | Y9: =(((H9*10^9)/0.037679)/14.2)/(H49*1000) -> 0.4231346 | Z9: =(((I9*10^9)/0.037679)/14.2)/(I49*1000) -> 0.56382431 | AA9: =(((J9*10^9)/0.037679)/14.2)/(J49*1000) -> 0.61528748 | ... AF9: =(((O9*10^9)/0.037679)/14.2)/(O49*1000) -> 0.71375607
A10: DL | B10: resid urban cooking | C10: 5.16989e-05 | D10: 5.42961e-05 | E10: 0.0020832971 | F10: 0.0040955362 | G10: 0.0062391222 | H10: 0.0085074267 | I10: 0.011159761 | J10: 0.013095676 | K10: 0.014890535 | L10: 0.016608584 | M10: 0.018344353 | N10: 0.020025103 | O10: 0.021674699 | R10: DL | S10: resid urban cooking | T10: =(((C10*10^9)/0.037679)/14.2)/(C50*1000) -> 0.0059029818 | U10: =(((D10*10^9)/0.037679)/14.2)/(D50*1000) -> 0.0055101324 | V10: =(((E10*10^9)/0.037679)/14.2)/(E50*1000) -> 0.19051321 | W10: =(((F10*10^9)/0.037679)/14.2)/(F50*1000) -> 0.34303146 | X10: =(((G10*10^9)/0.037679)/14.2)/(G50*1000) -> 0.4797482 | Y10: =(((H10*10^9)/0.037679)/14.2)/(H50*1000) -> 0.60400492 | Z10: =(((I10*10^9)/0.037679)/14.2)/(I50*1000) -> 0.73861981 | AA10: =(((J10*10^9)/0.037679)/14.2)/(J50*1000) -> 0.81759407 | ... AF10: =(((O10*10^9)/0.037679)/14.2)/(O50*1000) -> 1.140104
A11: DN | B11: resid urban cooking | C11: 0 | D11: 0 | E11: 0 | F11: 8.65615e-06 | G11: 0.00011827712 | H11: 0.00030853788 | I11: 0.00049276557 | J11: 0.00062837697 | K11: 0.00074801883 | L11: 0.0008290297 | M11: 0.0009025778 | N11: 0.0009684091 | O11: 0.0010361469 | R11: DN | S11: resid urban cooking | T11: =(((C11*10^9)/0.037679)/14.2)/(C51*1000) -> 0 | U11: =(((D11*10^9)/0.037679)/14.2)/(D51*1000) -> 0 | V11: =(((E11*10^9)/0.037679)/14.2)/(E51*1000) -> 0 | W11: =(((F11*10^9)/0.037679)/14.2)/(F51*1000) -> 0.02639226 | X11: =(((G11*10^9)/0.037679)/14.2)/(G51*1000) -> 0.24133347 | Y11: =(((H11*10^9)/0.037679)/14.2)/(H51*1000) -> 0.4699153 | Z11: =(((I11*10^9)/0.037679)/14.2)/(I51*1000) -> 0.62154815 | AA11: =(((J11*10^9)/0.037679)/14.2)/(J51*1000) -> 0.69996581 | ... AF11: =(((O11*10^9)/0.037679)/14.2)/(O51*1000) -> 0.87829177
A12: GA | B12: resid urban cooking | C12: 0 | D12: 0 | E12: 0 | F12: 0 | G12: 1.54487e-07 | H12: 0.00047942514 | I12: 0.00096527018 | J12: 0.0012203912 | K12: 0.0014200123 | L12: 0.0015401873 | M12: 0.0016421842 | N12: 0.0017343637 | O12: 0.0018310473 | R12: GA | S12: resid urban cooking | T12: =(((C12*10^9)/0.037679)/14.2)/(C52*1000) -> 0 | U12: =(((D12*10^9)/0.037679)/14.2)/(D52*1000) -> 0 | V12: =(((E12*10^9)/0.037679)/14.2)/(E52*1000) -> 0 | W12: =(((F12*10^9)/0.037679)/14.2)/(F52*1000) -> 0 | X12: =(((G12*10^9)/0.037679)/14.2)/(G52*1000) -> 0.00021091175 | Y12: =(((H12*10^9)/0.037679)/14.2)/(H52*1000) -> 0.60462331 | Z12: =(((I12*10^9)/0.037679)/14.2)/(I52*1000) -> 1.1672052 | AA12: =(((J12*10^9)/0.037679)/14.2)/(J52*1000) -> 1.4254011 | ... AF12: =(((O12*10^9)/0.037679)/14.2)/(O52*1000) -> 1.9839136
A13: GJ | B13: resid urban cooking | C13: 9.67003e-05 | D13: 7.5562727e-05 | E13: 0.0018505746 | F13: 0.018366573 | G13: 0.032100726 | H13: 0.042635882 | I13: 0.056180164 | J13: 0.066725727 | K13: 0.07754306 | L13: 0.08745875 | M13: 0.097499 | N13: 0.10738693 | O13: 0.11710867 | R13: GJ | S13: resid urban cooking | T13: =(((C13*10^9)/0.037679)/14.2)/(C53*1000) -> 0.0070201633 | U13: =(((D13*10^9)/0.037679)/14.2)/(D53*1000) -> 0.0047943683 | V13: =(((E13*10^9)/0.037679)/14.2)/(E53*1000) -> 0.10381953 | W13: =(((F13*10^9)/0.037679)/14.2)/(F53*1000) -> 0.92297701 | X13: =(((G13*10^9)/0.037679)/14.2)/(G53*1000) -> 1.463262 | Y13: =(((H13*10^9)/0.037679)/14.2)/(H53*1000) -> 1.7820294 | Z13: =(((I13*10^9)/0.037679)/14.2)/(I53*1000) -> 2.1739025 | AA13: =(((J13*10^9)/0.037679)/14.2)/(J53*1000) -> 2.473183 | ... AF13: =(((O13*10^9)/0.037679)/14.2)/(O53*1000) -> 3.8052105
... A38: WB | B38: resid urban cooking | C38: 0 | D38: 0 | E38: 9.81556e-06 | F38: 0.011057723 | G38: 0.021757464 | H38: 0.030177868 | I38: 0.040409781 | J38: 0.046566563 | K38: 0.05272977 | L38: 0.05770508 | M38: 0.0630024 | N38: 0.06824541 | O38: 0.07342275 | R38: WB | S38: resid urban cooking | T38: =(((C38*10^9)/0.037679)/14.2)/(C78*1000) -> 0 | U38: =(((D38*10^9)/0.037679)/14.2)/(D78*1000) -> 0 | V38: =(((E38*10^9)/0.037679)/14.2)/(E78*1000) -> 0.00051999455 | W38: =(((F38*10^9)/0.037679)/14.2)/(F78*1000) -> 0.54035679 | X38: =(((G38*10^9)/0.037679)/14.2)/(G78*1000) -> 0.99018653 | Y38: =(((H38*10^9)/0.037679)/14.2)/(H78*1000) -> 1.2919241 | Z38: =(((I38*10^9)/0.037679)/14.2)/(I78*1000) -> 1.6286332 | AA38: =(((J38*10^9)/0.037679)/14.2)/(J78*1000) -> 1.8442701 | ... AF38: =(((O38*10^9)/0.037679)/14.2)/(O78*1000) -> 2.8743557
R40: Cylinder/HH
A41: region | B41: Consumer | C41: 2010 | D41: 2015 | E41: 2020 | F41: 2025 | G41: 2030 | H41: 2035 | I41: 2040 | J41: 2045 | K41: 2050 | L41: 2055 | M41: 2060 | N41: 2065 | O41: 2070 | R41: region | S41: sector | T41: 2010 | U41: 2015 | V41: 2020 | W41: 2025 | X41: 2030 | Y41: 2035 | Z41: 2040 | AA41: 2045 | AB41: 2050 | AC41: 2055 | AD41: 2060 | AE41: 2065 | AF41: 2070
A42: AN | B42: resid urban | C42: 143 | D42: 157.597 | E42: 172 | F42: 187.833 | G42: 204.39 | H42: 221.252 | I42: 240.717 | J42: 253.127 | K42: 267.206 | L42: 280.682 | M42: 293.476 | N42: 304.242 | O42: 314.084 | R42: AN | S42: resid urban cooking | T42: =T2*4 -> 0 | U42: =U2*4 -> 0 | V42: =V2*4 -> 0.089978191 | W42: =W2*4 -> 1.3388927 | X42: =X2*4 -> 5.2270167 | Y42: =Y2*4 -> 7.9876067 | Z42: =Z2*4 -> 9.9000541 | AA42: =AA2*4 -> 11.01462 | ... AF42: =AF2*4 -> 14.561462
A43: AP | B43: resid urban | C43: 14610 | D43: 16609 | E43: 18618 | F43: 20573 | G43: 22475.6 | H43: 24379.8 | I43: 26290.1 | J43: 28011.2 | K43: 29033.4 | L43: 29968.4 | M43: 30207 | N43: 30276.7 | O43: 30178 | R43: AP | S43: resid urban cooking | T43: =T3*4 -> 0 | U43: =U3*4 -> 0.031406753 | V43: =V3*4 -> 0.2257676 | W43: =W3*4 -> 2.2491507 | X43: =X3*4 -> 3.7734248 | Y43: =Y3*4 -> 5.1511936 | Z43: =Z3*4 -> 6.6246468 | AA43: =AA3*4 -> 7.5673906 | ... AF43: =AF3*4 -> 12.018841
A44: AR | B44: resid urban | C44: 317 | D44: 351 | E44: 386 | F44: 422 | G44: 458 | H44: 495.57 | I44: 537.645 | J44: 564.561 | K44: 588.354 | L44: 604.275 | M44: 615.798 | N44: 624.662 | O44: 630.134 | R44: AR | S44: resid urban cooking | T44: =T4*4 -> 0 | U44: =U4*4 -> 0 | V44: =V4*4 -> 0.040056528 | W44: =W4*4 -> 3.2057875 | X44: =X4*4 -> 5.9687534 | Y44: =Y4*4 -> 8.5669797 | Z44: =Z4*4 -> 11.025367 | AA44: =AA4*4 -> 13.07069 | ... AF44: =AF4*4 -> 20.917698
A45: AS | B45: resid urban | C45: 4399 | D45: 4879 | E45: 5368 | F45: 5848 | G45: 6318 | H45: 6762 | I45: 7638.4 | J45: 8490.92 | K45: 9314.85 | L45: 10135.7 | M45: 10923.7 | N45: 11659.4 | O45: 12331.9 | R45: AS | S45: resid urban cooking | T45: =T5*4 -> 0.0069679212 | U45: =U5*4 -> 0.004849305 | V45: =V5*4 -> 0.061777267 | W45: =W5*4 -> 4.2884121 | X45: =X5*4 -> 8.0658722 | Y45: =Y5*4 -> 11.586648 | Z45: =Z5*4 -> 15.550516 | AA45: =AA5*4 -> 17.479224 | ... AF45: =AF5*4 -> 23.909567
A46: BR | B46: resid urban | C46: 11758 | D46: 13375 | E46: 14917 | F46: 16554 | G46: 18199 | H46: 19741 | I46: 21527.9 | J46: 23681.5 | K46: 25765 | L46: 28508.4 | M46: 31131.7 | N46: 34432 | O46: 37545.7 | R46: BR | S46: resid urban cooking | T46: =T6*4 -> 0 | U46: =U6*4 -> 0 | V46: =V6*4 -> 0 | W46: =W6*4 -> 2.3238444 | X46: =X6*4 -> 8.6759538 | Y46: =Y6*4 -> 10.293695 | Z46: =Z6*4 -> 12.26822 | AA46: =AA6*4 -> 12.936598 | ... AF46: =AF6*4 -> 16.434926
A47: CG | B47: resid urban | C47: 5937 | D47: 6858 | E47: 7810 | F47: 8763 | G47: 9708 | H47: 10660 | I47: 11597.2 | J47: 11991.7 | K47: 12324.9 | L47: 12633.4 | M47: 12891.7 | N47: 13088.8 | O47: 13221.4 | R47: CG | S47: resid urban cooking | T47: =T7*4 -> 0 | U47: =U7*4 -> 0 | V47: =V7*4 -> 0 | W47: =W7*4 -> 0 | X47: =X7*4 -> 5.4273992 | Y47: =Y7*4 -> 6.8837041 | Z47: =Z7*4 -> 8.5941972 | AA47: =AA7*4 -> 9.9564332 | ... AF47: =AF7*4 -> 16.619045
A48: CH | B48: resid urban | C48: 1026 | D48: 1123 | E48: 1195.92 | F48: 1254.33 | G48: 1317.69 | H48: 1382.04 | I48: 1445.4 | J48: 1533.51 | K48: 1609.74 | L48: 1670.13 | M48: 1718.64 | N48: 1759.23 | O48: 1790.91 | R48: CH | S48: resid urban cooking | T48: =T8*4 -> 0 | U48: =U8*4 -> 0 | V48: =V8*4 -> 0.0017827887 | W48: =W8*4 -> 0.75575646 | X48: =X8*4 -> 1.4476839 | Y48: =Y8*4 -> 1.9240008 | Z48: =Z8*4 -> 2.3911067 | AA48: =AA8*4 -> 2.6266542 | ... AF48: =AF8*4 -> 3.5945706
A49: DD | B49: resid urban | C49: 183 | D49: 287 | E49: 441 | F49: 686 | G49: 1056.87 | H49: 1426.78 | I49: 1784.97 | J49: 2147.31 | K49: 2385.9 | L49: 2625.48 | M49: 2723.49 | N49: 2807.64 | O49: 2876.94 | R49: DD | S49: resid urban cooking | T49: =T9*4 -> 0 | U49: =U9*4 -> 0 | V49: =V9*4 -> 0 | W49: =W9*4 -> 0.018555865 | X49: =X9*4 -> 0.86144637 | Y49: =Y9*4 -> 1.6925384 | Z49: =Z9*4 -> 2.2552973 | AA49: =AA9*4 -> 2.4611499 | ... AF49: =AF9*4 -> 2.8550243
A50: DL | B50: resid urban | C50: 16369 | D50: 18417 | E50: 20438 | F50: 22314.6 | G50: 24306.5 | H50: 26325.1 | I50: 28238.8 | J50: 29936.6 | K50: 31429.5 | L50: 32707.6 | M50: 33823.3 | N50: 34768.8 | O50: 35532.1 | R50: DL | S50: resid urban cooking | T50: =T10*4 -> 0.023611927 | U50: =U10*4 -> 0.02204053 | V50: =V10*4 -> 0.76205285 | W50: =W10*4 -> 1.3721258 | X50: =X10*4 -> 1.9189928 | Y50: =Y10*4 -> 2.4160197 | Z50: =Z10*4 -> 2.9544792 | AA50: =AA10*4 -> 3.2703763 | ... AF50: =AF10*4 -> 4.5604162
A51: DN | B51: resid urban | C51: 161 | D51: 264 | E51: 408 | F51: 613 | G51: 916 | H51: 1227.16 | I51: 1481.76 | J51: 1677.86 | K51: 1880.56 | L51: 2007.9 | M51: 2097.55 | N51: 2156.7 | O51: 2204.93 | R51: DN | S51: resid urban cooking | T51: =T11*4 -> 0 | U51: =U11*4 -> 0 | V51: =V11*4 -> 0 | W51: =W11*4 -> 0.10556904 | X51: =X11*4 -> 0.96533387 | Y51: =Y11*4 -> 1.8796612 | Z51: =Z11*4 -> 2.4861926 | AA51: =AA11*4 -> 2.7998632 | ... AF51: =AF11*4 -> 3.5131671
A52: GA | B52: resid urban | C52: 907 | D52: 1029 | E52: 1148 | F52: 1262 | G52: 1369 | H52: 1482 | I52: 1545.66 | J52: 1600.2 | K52: 1655.29 | L52: 1699.24 | M52: 1716.72 | N52: 1725.92 | O52: 1725 | R52: GA | S52: resid urban cooking | T52: =T12*4 -> 0 | U52: =U12*4 -> 0 | V52: =V12*4 -> 0 | W52: =W12*4 -> 0 | X52: =X12*4 -> 0.00084364701 | Y52: =Y12*4 -> 2.4184933 | Z52: =Z12*4 -> 4.6688208 | AA52: =AA12*4 -> 5.7016046 | ... AF52: =AF12*4 -> 7.9356543
A53: GJ | B53: resid urban | C53: 25745 | D53: 29457 | E53: 33315 | F53: 37192 | G53: 41002 | H53: 44717 | I53: 48300.9 | J53: 50425.4 | K53: 52324.6 | L53: 53993 | M53: 55426 | N53: 56607.2 | O53: 57520.5 | R53: GJ | S53: resid urban cooking | T53: =T13*4 -> 0.028080653 | U53: =U13*4 -> 0.019177473 | V53: =V13*4 -> 0.41527814 | W53: =W13*4 -> 3.691908 | X53: =X13*4 -> 5.853048 | Y53: =Y13*4 -> 7.1281178 | Z53: =Z13*4 -> 8.6956101 | AA53: =AA13*4 -> 9.8927319 | ... AF53: =AF13*4 -> 15.220842
... A78: WB | B78: resid urban | C78: 29093 | D78: 32232 | E78: 35280 | F78: 38247 | G78: 41068 | H78: 43658 | I78: 46374.1 | J78: 47191.3 | K78: 47772.2 | L78: 48158.3 | M78: 48288.6 | N78: 48148.7 | O78: 47742.2 | R78: WB | S78: resid urban cooking | T78: =T38*4 -> 0 | U78: =U38*4 -> 0 | V78: =V38*4 -> 0.0020799782 | W78: =W38*4 -> 2.1614272 | X78: =X38*4 -> 3.9607461 | Y78: =Y38*4 -> 5.1676964 | Z78: =Z38*4 -> 6.5145329 | AA78: =AA38*4 -> 7.3770804 | ... AF78: =AF38*4 -> 11.497423

Sheet LPGCylinderHH
A1: region | B1: sector | C1: 2010 | D1: 2015 | E1: 2020 | F1: 2025 | G1: 2030 | H1: 2035 | I1: 2040 | J1: 2045 | K1: 2050 | L1: 2055 | M1: 2060 | N1: 2065 | O1: 2070 | R1: region | S1: sector | T1: 2010 | U1: 2015 | V1: 2020 | W1: 2025 | X1: 2030 | Y1: 2035 | Z1: 2040 | AA1: 2045 | AB1: 2050 | AC1: 2055 | AD1: 2060 | AE1: 2065 | AF1: 2070
A2: AN | B2: resid rural cooking | C2: 0.000110619 | D2: 8.540634e-05 | E2: 7.2847609e-05 | F2: 5.7743017e-05 | G2: 4.9208883e-05 | H2: 4.3385881e-05 | I2: 2.6608071e-05 | J2: 3.1032846e-05 | K2: 3.3717328e-05 | L2: 3.442616e-05 | M2: 3.426355e-05 | N2: 3.384056e-05 | O2: 3.318604e-05 | R2: AN | S2: resid rural cooking | T2: =(((C2*10^9)/0.0496)/14.2)/(C79*1000) -> 0.65990702 | U2: =(((D2*10^9)/0.0496)/14.2)/(D79*1000) -> 0.51953362 | V2: =(((E2*10^9)/0.0496)/14.2)/(E79*1000) -> 0.45363905 | W2: =(((F2*10^9)/0.0496)/14.2)/(F79*1000) -> 0.36901999 | X2: =(((G2*10^9)/0.0496)/14.2)/(G79*1000) -> 0.32555437 | Y2: =(((H2*10^9)/0.0496)/14.2)/(H79*1000) -> 0.29651151 | Z2: =(((I2*10^9)/0.0496)/14.2)/(I79*1000) -> 0.19149336 | AA2: =(((J2*10^9)/0.0496)/14.2)/(J79*1000) -> 0.22609966 | ... AF2: =(((O2*10^9)/0.0496)/14.2)/(O79*1000) -> 0.27730081
A3: AP | B3: resid rural cooking | C3: 0.00799735 | D3: 0.006515958 | E3: 0.008379968 | F3: 0.010217245 | G3: 0.011925969 | H3: 0.011996792 | I3: 0.010554507 | J3: 0.009980442 | K3: 0.009351266 | L3: 0.008983531 | M3: 0.008827834 | N3: 0.008722586 | O3: 0.008600044 | R3: AP | S3: resid rural cooking | T3: =(((C3*10^9)/0.0496)/14.2)/(C80*1000) -> 0.32472648 | U3: =(((D3*10^9)/0.0496)/14.2)/(D80*1000) -> 0.26613592 | V3: =(((E3*10^9)/0.0496)/14.2)/(E80*1000) -> 0.34820906 | W3: =(((F3*10^9)/0.0496)/14.2)/(F80*1000) -> 0.43778785 | X3: =(((G3*10^9)/0.0496)/14.2)/(G80*1000) -> 0.53348835 | Y3: =(((H3*10^9)/0.0496)/14.2)/(H80*1000) -> 0.56563753 | Z3: =(((I3*10^9)/0.0496)/14.2)/(I80*1000) -> 0.52615564 | AA3: =(((J3*10^9)/0.0496)/14.2)/(J80*1000) -> 0.52652727 | ... AF3: =(((O3*10^9)/0.0496)/14.2)/(O80*1000) -> 0.55875264
A4: AR | B4: resid rural cooking | C4: 0.000195849 | D4: 0.00015573647 | E4: 0.00017213708 | F4: 0.00018249643 | G4: 0.00018618433 | H4: 0.00019412024 | I4: 0.00017840138 | J4: 0.00019713339 | K4: 0.00020878821 | L4: 0.00021696268 | M4: 0.00022596545 | N4: 0.00023536499 | O4: 0.00024472213 | R4: AR | S4: resid rural cooking | T4: =(((C4*10^9)/0.0496)/14.2)/(C81*1000) -> 0.2606075 | U4: =(((D4*10^9)/0.0496)/14.2)/(D81*1000) -> 0.19956324 | V4: =(((E4*10^9)/0.0496)/14.2)/(E81*1000) -> 0.21307917 | W4: =(((F4*10^9)/0.0496)/14.2)/(F81*1000) -> 0.21921329 | X4: =(((G4*10^9)/0.0496)/14.2)/(G81*1000) -> 0.21828755 | Y4: =(((H4*10^9)/0.0496)/14.2)/(H81*1000) -> 0.22237133 | Z4: =(((I4*10^9)/0.0496)/14.2)/(I81*1000) -> 0.20049544 | AA4: =(((J4*10^9)/0.0496)/14.2)/(J81*1000) -> 0.21440418 | ... AF4: =(((O4*10^9)/0.0496)/14.2)/(O81*1000) -> 0.25874338
A5: AS | B5: resid rural cooking | C5: 0.00597252 | D5: 0.004859828 | E5: 0.00654032 | F5: 0.006770394 | G5: 0.006634789 | H5: 0.0063634947 | I5: 0.0054728142 | J5: 0.005395664 | K5: 0.005229223 | L5: 0.005145931 | M5: 0.005109802 | N5: 0.005097396 | O5: 0.00508964 | R5: AS | S5: resid rural cooking | T5: =(((C5*10^9)/0.0496)/14.2)/(C82*1000) -> 0.31632927 | U5: =(((D5*10^9)/0.0496)/14.2)/(D82*1000) -> 0.24391206 | V5: =(((E5*10^9)/0.0496)/14.2)/(E82*1000) -> 0.31292355 | W5: =(((F5*10^9)/0.0496)/14.2)/(F82*1000) -> 0.31140197 | X5: =(((G5*10^9)/0.0496)/14.2)/(G82*1000) -> 0.29550581 | Y5: =(((H5*10^9)/0.0496)/14.2)/(H82*1000) -> 0.27683145 | Z5: =(((I5*10^9)/0.0496)/14.2)/(I82*1000) -> 0.23737427 | AA5: =(((J5*10^9)/0.0496)/14.2)/(J82*1000) -> 0.2351739 | ... AF5: =(((O5*10^9)/0.0496)/14.2)/(O82*1000) -> 0.24472681
A6: BR | B6: resid rural cooking | C6: 0.0144475 | D6: 0.01117655 | E6: 0.0093809611 | F6: 0.036037263 | G6: 0.065609995 | H6: 0.10486109 | I6: 0.13556586 | J6: 0.16769859 | K6: 0.20031267 | L6: 0.21329013 | M6: 0.22227689 | N6: 0.22519507 | O6: 0.22542291 | R6: BR | S6: resid rural cooking | T6: =(((C6*10^9)/0.0496)/14.2)/(C83*1000) -> 0.22214069 | U6: =(((D6*10^9)/0.0496)/14.2)/(D83*1000) -> 0.15742471 | V6: =(((E6*10^9)/0.0496)/14.2)/(E83*1000) -> 0.12313643 | W6: =(((F6*10^9)/0.0496)/14.2)/(F83*1000) -> 0.44218819 | X6: =(((G6*10^9)/0.0496)/14.2)/(G83*1000) -> 0.75832104 | Y6: =(((H6*10^9)/0.0496)/14.2)/(H83*1000) -> 1.1556078 | Z6: =(((I6*10^9)/0.0496)/14.2)/(I83*1000) -> 1.4554846 | AA6: =(((J6*10^9)/0.0496)/14.2)/(J83*1000) -> 1.7742837 | ... AF6: =(((O6*10^9)/0.0496)/14.2)/(O83*1000) -> 2.5462824
A7: CG | B7: resid rural cooking | C7: 0.0034731 | D7: 0.0026808442 | E7: 0.0022499737 | F7: 0.002418215 | G7: 0.0039415381 | H7: 0.010474144 | I7: 0.016355632 | J7: 0.022845216 | K7: 0.028863498 | L7: 0.032454075 | M7: 0.035043685 | N7: 0.03667983 | O7: 0.03789538 | R7: CG | S7: resid rural cooking | T7: =(((C7*10^9)/0.0496)/14.2)/(C84*1000) -> 0.25148609 | U7: =(((D7*10^9)/0.0496)/14.2)/(D84*1000) -> 0.1837632 | V7: =(((E7*10^9)/0.0496)/14.2)/(E84*1000) -> 0.14732893 | W7: =(((F7*10^9)/0.0496)/14.2)/(F84*1000) -> 0.15294921 | X7: =(((G7*10^9)/0.0496)/14.2)/(G84*1000) -> 0.24319812 | Y7: =(((H7*10^9)/0.0496)/14.2)/(H84*1000) -> 0.63495521 | Z7: =(((I7*10^9)/0.0496)/14.2)/(I84*1000) -> 0.99486226 | AA7: =(((J7*10^9)/0.0496)/14.2)/(J84*1000) -> 1.3764825 | ... AF7: =(((O7*10^9)/0.0496)/14.2)/(O84*1000) -> 2.3416958
A8: CH | B8: resid rural cooking | C8: 0.000166637 | D8: 0.0001356532 | E8: 0.00015654848 | F8: 0.00019941803 | G8: 0.0002178379 | H8: 0.00021932587 | I8: 0.00020352442 | J8: 0.0002119867 | K8: 0.00021827544 | L8: 0.00022592797 | M8: 0.00023629422 | N8: 0.00024879582 | O8: 0.00026244054 | R8: CH | S8: resid rural cooking | T8: =(((C8*10^9)/0.0496)/14.2)/(C85*1000) -> 8.1583704 | U8: =(((D8*10^9)/0.0496)/14.2)/(D85*1000) -> 14.815512 | V8: =(((E8*10^9)/0.0496)/14.2)/(E85*1000) -> 18.399749 | W8: =(((F8*10^9)/0.0496)/14.2)/(F85*1000) -> 22.346926 | X8: =(((G8*10^9)/0.0496)/14.2)/(G85*1000) -> 23.237284 | Y8: =(((H8*10^9)/0.0496)/14.2)/(H85*1000) -> 22.306654 | Z8: =(((I8*10^9)/0.0496)/14.2)/(I85*1000) -> 19.792181 | AA8: =(((J8*10^9)/0.0496)/14.2)/(J85*1000) -> 19.430643 | ... AF8: =(((O8*10^9)/0.0496)/14.2)/(O85*1000) -> 20.597871
A9: DD | B9: resid rural cooking | C9: 3.33953e-05 | D9: 2.57774e-05 | E9: 2.16343e-05 | F9: 9.62831e-06 | G9: 1.298082e-05 | H9: 9.574585e-06 | I9: 5.527166e-06 | J9: 8.258458e-06 | K9: 1.136221e-05 | L9: 1.3762904e-05 | M9: 1.5341525e-05 | N9: 1.6376875e-05 | O9: 1.6657541e-05 | R9: DD | S9: resid rural cooking | T9: =(((C9*10^9)/0.0496)/14.2)/(C86*1000) -> 0.79024922 | U9: =(((D9*10^9)/0.0496)/14.2)/(D86*1000) -> 0.8714045 | V9: =(((E9*10^9)/0.0496)/14.2)/(E86*1000) -> 1.0970206 | W9: =(((F9*10^9)/0.0496)/14.2)/(F86*1000) -> 0.71949278 | X9: =(((G9*10^9)/0.0496)/14.2)/(G86*1000) -> 1.304402 | Y9: =(((H9*10^9)/0.0496)/14.2)/(H86*1000) -> 1.3304837 | Z9: =(((I9*10^9)/0.0496)/14.2)/(I86*1000) -> 0.43524798 | AA9: =(((J9*10^9)/0.0496)/14.2)/(J86*1000) -> 0.54059172 | ... AF9: =(((O9*10^9)/0.0496)/14.2)/(O86*1000) -> 0.81385167
A10: DL | B10: resid rural cooking | C10: 0.00301666 | D10: 0.0023579291 | E10: 0.0021105682 | F10: 0.0028358287 | G10: 0.0028843791 | H10: 0.002922683 | I10: 0.0026360496 | J10: 0.0027245744 | K10: 0.002770392 | L10: 0.0028031637 | M10: 0.0028764913 | N10: 0.002962182 | O10: 0.0030496736 | R10: DL | S10: resid rural cooking | T10: =(((C10*10^9)/0.0496)/14.2)/(C87*1000) -> 10.222152 | U10: =(((D10*10^9)/0.0496)/14.2)/(D87*1000) -> 12.87619 | V10: =(((E10*10^9)/0.0496)/14.2)/(E87*1000) -> 22.530858 | W10: =(((F10*10^9)/0.0496)/14.2)/(F87*1000) -> 17.863068 | X10: =(((G10*10^9)/0.0496)/14.2)/(G87*1000) -> 16.679977 | Y10: =(((H10*10^9)/0.0496)/14.2)/(H87*1000) -> 15.605476 | Z10: =(((I10*10^9)/0.0496)/14.2)/(I87*1000) -> 13.121187 | AA10: =(((J10*10^9)/0.0496)/14.2)/(J87*1000) -> 12.792671 | ... AF10: =(((O10*10^9)/0.0496)/14.2)/(O87*1000) -> 12.064179
A11: DN | B11: resid rural cooking | C11: 3.5197e-05 | D11: 2.71681e-05 | E11: 2.28016e-05 | F11: 1.8008439e-05 | G11: 2.093161e-05 | H11: 3.2578015e-05 | I11: 4.219605e-05 | J11: 4.6371634e-05 | K11: 5.6893519e-05 | L11: 6.092115e-05 | M11: 6.521529e-05 | N11: 6.968434e-05 | O11: 7.395713e-05 | R11: DN | S11: resid rural cooking | T11: =(((C11*10^9)/0.0496)/14.2)/(C88*1000) -> 0.27307663 | U11: =(((D11*10^9)/0.0496)/14.2)/(D88*1000) -> 0.20517829 | V11: =(((E11*10^9)/0.0496)/14.2)/(E88*1000) -> 0.1618696 | W11: =(((F11*10^9)/0.0496)/14.2)/(F88*1000) -> 0.11465716 | X11: =(((G11*10^9)/0.0496)/14.2)/(G88*1000) -> 0.11343089 | Y11: =(((H11*10^9)/0.0496)/14.2)/(H88*1000) -> 0.15741412 | Z11: =(((I11*10^9)/0.0496)/14.2)/(I88*1000) -> 0.21226736 | AA11: =(((J11*10^9)/0.0496)/14.2)/(J88*1000) -> 0.24104442 | ... AF11: =(((O11*10^9)/0.0496)/14.2)/(O88*1000) -> 0.48151975
A12: GA | B12: resid rural cooking | C12: 0.000437544 | D12: 0.000337735 | E12: 0.000283453 | F12: 0.000195626 | G12: 0.00015409328 | H12: 0.00010640353 | I12: 2.5032069e-05 | J12: 3.7022589e-05 | K12: 4.9430518e-05 | L12: 5.395843e-05 | M12: 5.8314531e-05 | N12: 6.12027e-05 | O12: 6.375387e-05 | R12: GA | S12: resid rural cooking | T12: =(((C12*10^9)/0.0496)/14.2)/(C89*1000) -> 1.1254148 | U12: =(((D12*10^9)/0.0496)/14.2)/(D89*1000) -> 0.99279348 | V12: =(((E12*10^9)/0.0496)/14.2)/(E89*1000) -> 0.97919506 | W12: =(((F12*10^9)/0.0496)/14.2)/(F89*1000) -> 0.82418869 | X12: =(((G12*10^9)/0.0496)/14.2)/(G89*1000) -> 0.82872368 | Y12: =(((H12*10^9)/0.0496)/14.2)/(H89*1000) -> 0.76297805 | Z12: =(((I12*10^9)/0.0496)/14.2)/(I89*1000) -> 0.19599505 | AA12: =(((J12*10^9)/0.0496)/14.2)/(J89*1000) -> 0.29564124 | ... AF12: =(((O12*10^9)/0.0496)/14.2)/(O89*1000) -> 0.60345553
A13: GJ | B13: resid rural cooking | C13: 0.0165675 | D13: 0.01280222 | E13: 0.010745074 | F13: 0.017390931 | G13: 0.02177886 | H13: 0.02912329 | I13: 0.030088917 | J13: 0.03174838 | K13: 0.03164692 | L13: 0.03036951 | M13: 0.02940467 | N13: 0.02844642 | O13: 0.02752517 | R13: GJ | S13: resid rural cooking | T13: =(((C13*10^9)/0.0496)/14.2)/(C90*1000) -> 0.67798497 | U13: =(((D13*10^9)/0.0496)/14.2)/(D90*1000) -> 0.50913728 | V13: =(((E13*10^9)/0.0496)/14.2)/(E90*1000) -> 0.41828077 | W13: =(((F13*10^9)/0.0496)/14.2)/(F90*1000) -> 0.66926338 | X13: =(((G13*10^9)/0.0496)/14.2)/(G90*1000) -> 0.83733179 | Y13: =(((H13*10^9)/0.0496)/14.2)/(H90*1000) -> 1.129799 | Z13: =(((I13*10^9)/0.0496)/14.2)/(I90*1000) -> 1.2150975 | AA13: =(((J13*10^9)/0.0496)/14.2)/(J90*1000) -> 1.3029211 | ... AF13: =(((O13*10^9)/0.0496)/14.2)/(O90*1000) -> 1.3815462
... A75: WB | B75: resid urban cooking | C75: 0.048622 | D75: 0.037667725 | E75: 0.034214869 | F75: 0.029851568 | G75: 0.024409562 | H75: 0.019257247 | I75: 0.0095033634 | J75: 0.010282578 | K75: 0.011567381 | L75: 0.013271605 | M75: 0.015163943 | N75: 0.017159979 | O75: 0.019006671 | R75: WB | S75: resid urban cooking | T75: =(((C75*10^9)/0.0496)/14.2)/(C152*1000) -> 2.3728719 | U75: =(((D75*10^9)/0.0496)/14.2)/(D152*1000) -> 1.6592511 | V75: =(((E75*10^9)/0.0496)/14.2)/(E152*1000) -> 1.376944 | W75: =(((F75*10^9)/0.0496)/14.2)/(F152*1000) -> 1.108153 | X75: =(((G75*10^9)/0.0496)/14.2)/(G152*1000) -> 0.84389113 | Y75: =(((H75*10^9)/0.0496)/14.2)/(H152*1000) -> 0.62626819 | Z75: =(((I75*10^9)/0.0496)/14.2)/(I152*1000) -> 0.29095902 | AA75: =(((J75*10^9)/0.0496)/14.2)/(J152*1000) -> 0.3093642 | ... AF75: =(((O75*10^9)/0.0496)/14.2)/(O152*1000) -> 0.56524094
R77: Cylinder/HH
A78: region | B78: Consumer | C78: 2010 | D78: 2015 | E78: 2020 | F78: 2025 | G78: 2030 | H78: 2035 | I78: 2040 | J78: 2045 | K78: 2050 | L78: 2055 | M78: 2060 | N78: 2065 | O78: 2070 | R78: region | S78: sector | T78: 2010 | U78: 2015 | V78: 2020 | W78: 2025 | X78: 2030 | Y78: 2035 | Z78: 2040 | AA78: 2045 | AB78: 2050 | AC78: 2055 | AD78: 2060 | AE78: 2065 | AF78: 2070 | AG78: Increase
A79: AN | B79: resid rural | C79: 238 | D79: 233.403 | E79: 228 | F79: 222.167 | G79: 214.61 | H79: 207.748 | I79: 197.283 | J79: 194.873 | K79: 192.794 | L79: 189.318 | M79: 184.524 | N79: 177.758 | O79: 169.916 | R79: AN | S79: resid rural cooking | T79: =T2*4 -> 2.6396281 | U79: =U2*4 -> 2.0781345 | V79: =V2*4 -> 1.8145562 | W79: =W2*4 -> 1.47608 | X79: =X2*4 -> 1.3022175 | Y79: =Y2*4 -> 1.186046 | Z79: =Z2*4 -> 0.76597343 | AA79: =AA2*4 -> 0.90439865 | ... AF79: =AF2*4 -> 1.1092032 | AG79: =AF79/V79 -> 0.61128073
A80: AP | B80: resid rural | C80: 34967 | D80: 34762 | E80: 34169 | F80: 33136 | G80: 31739.4 | H80: 30113.2 | I80: 28480.9 | J80: 26912.8 | K80: 25746.6 | L80: 24519.6 | M80: 23734 | N80: 22840.3 | O80: 21853 | R80: AP | S80: resid rural cooking | T80: =T3*4 -> 1.2989059 | U80: =U3*4 -> 1.0645437 | V80: =V3*4 -> 1.3928363 | W80: =W3*4 -> 1.7511514 | X80: =X3*4 -> 2.1339534 | Y80: =Y3*4 -> 2.2625501 | Z80: =Z3*4 -> 2.1046225 | AA80: =AA3*4 -> 2.1061091 | ... AF80: =AF3*4 -> 2.2350106 | AG80: =AF80/V80 -> 1.604647
A81: AR | B81: resid rural | C81: 1067 | D81: 1108 | E81: 1147 | F81: 1182 | G81: 1211 | H81: 1239.43 | I81: 1263.35 | J81: 1305.44 | K81: 1338.65 | L81: 1352.72 | M81: 1356.2 | N81: 1353.34 | O81: 1342.87 | R81: AR | S81: resid rural cooking | T81: =T4*4 -> 1.04243 | U81: =U4*4 -> 0.79825296 | V81: =V4*4 -> 0.85231667 | W81: =W4*4 -> 0.87685315 | X81: =X4*4 -> 0.87315019 | Y81: =Y4*4 -> 0.88948532 | Z81: =Z4*4 -> 0.80198178 | AA81: =AA4*4 -> 0.85761673 | ... AF81: =AF4*4 -> 1.0349735 | AG81: =AF81/V81 -> 1.2143063
A82: AS | B82: resid rural | C82: 26807 | D82: 28289 | E82: 29675 | F82: 30869 | G82: 31878 | H82: 32637 | I82: 32734.6 | J82: 32575.1 | K82: 32208.2 | L82: 31765.3 | M82: 31177.3 | N82: 30427.6 | O82: 29528.1 | R82: AS | S82: resid rural cooking | T82: =T5*4 -> 1.2653171 | U82: =U5*4 -> 0.97564826 | V82: =V5*4 -> 1.2516942 | W82: =W5*4 -> 1.2456079 | X82: =X5*4 -> 1.1820233 | Y82: =Y5*4 -> 1.1073258 | Z82: =Z5*4 -> 0.94949709 | AA82: =AA5*4 -> 0.94069559 | ... AF82: =AF5*4 -> 0.97890722 | AG82: =AF82/V82 -> 0.7820658
A83: BR | B83: resid rural | C83: 92341 | D83: 100801 | E83: 108166 | F83: 115711 | G83: 122842 | H83: 128835 | I83: 132243 | J83: 134195 | K83: 135266 | L83: 134397 | M83: 132719 | N83: 129530 | O83: 125696 | R83: BR | S83: resid rural cooking | T83: =T6*4 -> 0.88856274 | U83: =U6*4 -> 0.62969886 | V83: =V6*4 -> 0.49254571 | W83: =W6*4 -> 1.7687527 | X83: =X6*4 -> 3.0332842 | Y83: =Y6*4 -> 4.6224313 | Z83: =Z6*4 -> 5.8219385 | AA83: =AA6*4 -> 7.0971347 | ... AF83: =AF6*4 -> 10.18513 | AG83: =AF83/V83 -> 20.678547
A84: CG | B84: resid rural | C84: 19608 | D84: 20713 | E84: 21683 | F84: 22448 | G84: 23011 | H84: 23421 | I84: 23341.8 | J84: 23564.3 | K84: 23641.1 | L84: 23649.6 | M84: 23547.3 | N84: 23322.2 | O84: 22976.6 | R84: CG | S84: resid rural cooking | T84: =T7*4 -> 1.0059444 | U84: =U7*4 -> 0.73505281 | V84: =V7*4 -> 0.58931573 | W84: =W7*4 -> 0.61179684 | X84: =X7*4 -> 0.97279249 | Y84: =Y7*4 -> 2.5398208 | Z84: =Z7*4 -> 3.979449 | AA84: =AA7*4 -> 5.5059301 | ... AF84: =AF7*4 -> 9.3667833 | AG84: =AF84/V84 -> 15.894338
A85: CH | B85: resid rural | C85: 29 | D85: 13 | E85: 12.08 | F85: 12.67 | G85: 13.31 | H85: 13.96 | I85: 14.6 | J85: 15.49 | K85: 16.26 | L85: 16.87 | M85: 17.36 | N85: 17.77 | O85: 18.09 | R85: CH | S85: resid rural cooking | T85: =T8*4 -> 32.633482 | U85: =U8*4 -> 59.262049 | V85: =V8*4 -> 73.598996 | W85: =W8*4 -> 89.387703 | X85: =X8*4 -> 92.949136 | Y85: =Y8*4 -> 89.226614 | Z85: =Z8*4 -> 79.168724 | AA85: =AA8*4 -> 77.722573 | ... AF85: =AF8*4 -> 82.391484 | AG85: =AF85/V85 -> 1.1194648
A86: DD | B86: resid rural | C86: 60 | D86: 42 | E86: 28 | F86: 19 | G86: 14.1293 | H86: 10.2174 | I86: 18.03 | J86: 21.69 | K86: 24.1 | L86: 26.52 | M86: 27.51 | N86: 28.36 | O86: 29.06 | R86: DD | S86: resid rural cooking | T86: =T9*4 -> 3.1609969 | U86: =U9*4 -> 3.485618 | V86: =V9*4 -> 4.3880825 | W86: =W9*4 -> 2.8779711 | X86: =X9*4 -> 5.2176081 | Y86: =Y9*4 -> 5.3219346 | Z86: =Z9*4 -> 1.7409919 | AA86: =AA9*4 -> 2.1623669 | ... AF86: =AF9*4 -> 3.2554067 | AG86: =AF86/V86 -> 0.74187454
A87: DL | B87: resid rural | C87: 419 | D87: 260 | E87: 133 | F87: 225.4 | G87: 245.52 | H87: 265.91 | I87: 285.24 | J87: 302.39 | K87: 317.47 | L87: 330.38 | M87: 341.65 | N87: 351.2 | O87: 358.91 | R87: DL | S87: resid rural cooking | T87: =T10*4 -> 40.888607 | U87: =U10*4 -> 51.50476 | V87: =V10*4 -> 90.123432 | W87: =W10*4 -> 71.452274 | X87: =X10*4 -> 66.719907 | Y87: =Y10*4 -> 62.421905 | Z87: =Z10*4 -> 52.484748 | AA87: =AA10*4 -> 51.170683 | ... AF87: =AF10*4 -> 48.256717 | AG87: =AF87/V87 -> 0.53545139
A88: DN | B88: resid rural | C88: 183 | D88: 188 | E88: 200 | F88: 223 | G88: 262 | H88: 293.84 | I88: 282.24 | J88: 273.14 | K88: 256.44 | L88: 223.1 | M88: 207.45 | N88: 213.3 | O88: 218.07 | R88: DN | S88: resid rural cooking | T88: =T11*4 -> 1.0923065 | U88: =U11*4 -> 0.82071314 | V88: =V11*4 -> 0.64747842 | W88: =W11*4 -> 0.45862865 | X88: =X11*4 -> 0.45372354 | Y88: =Y11*4 -> 0.62965648 | Z88: =Z11*4 -> 0.84906943 | AA88: =AA11*4 -> 0.96417766 | ... AF88: =AF11*4 -> 1.926079 | AG88: =AF88/V88 -> 2.9747385
A89: GA | B89: resid rural | C89: 552 | D89: 483 | E89: 411 | F89: 337 | G89: 264 | H89: 198.004 | I89: 181.335 | J89: 177.8 | K89: 163.71 | L89: 147.76 | M89: 149.28 | N89: 150.08 | O89: 150 | R89: GA | S89: resid rural cooking | T89: =T12*4 -> 4.5016593 | U89: =U12*4 -> 3.9711739 | V89: =V12*4 -> 3.9167803 | W89: =W12*4 -> 3.2967548 | X89: =X12*4 -> 3.3148947 | Y89: =Y12*4 -> 3.0519122 | Z89: =Z12*4 -> 0.78398019 | AA89: =AA12*4 -> 1.1825649 | ... AF89: =AF12*4 -> 2.4138221 | AG89: =AF89/V89 -> 0.61627714
A90: GJ | B90: resid rural | C90: 34695 | D90: 35701 | E90: 36473 | F90: 36894 | G90: 36929 | H90: 36599 | I90: 35158.1 | J90: 34596.6 | K90: 33765.4 | L90: 32693 | M90: 31408 | N90: 29931.8 | O90: 28287.5 | R90: GJ | S90: resid rural cooking | T90: =T13*4 -> 2.7119399 | U90: =U13*4 -> 2.0365491 | V90: =V13*4 -> 1.6731231 | W90: =W13*4 -> 2.6770535 | X90: =X13*4 -> 3.3493272 | Y90: =Y13*4 -> 4.5191961 | Z90: =Z13*4 -> 4.86039 | AA90: =AA13*4 -> 5.2116845 | ... AF90: =AF13*4 -> 5.5261849 | AG90: =AF90/V90 -> 3.3029159
... A152: WB | B152: resid urban | C152: 29093 | D152: 32232 | E152: 35280 | F152: 38247 | G152: 41068 | H152: 43658 | I152: 46374.1 | J152: 47191.3 | K152: 47772.2 | L152: 48158.3 | M152: 48288.6 | N152: 48148.7 | O152: 47742.2 | R152: WB | S152: resid urban cooking | T152: =T75*4 -> 9.4914876 | U152: =U75*4 -> 6.6370044 | V152: =V75*4 -> 5.5077761 | W152: =W75*4 -> 4.4326122 | X152: =X75*4 -> 3.3755645 | Y152: =Y75*4 -> 2.5050728 | Z152: =Z75*4 -> 1.1638361 | AA152: =AA75*4 -> 1.2374568 | ... AF152: =AF75*4 -> 2.2609638 | AG152: =AF152/V152 -> 0.41050393

Sheet Pop RuralUrban
A1: region | B1: Consumer | C1: 2010 | D1: 2015 | E1: 2020 | F1: 2025 | G1: 2030 | H1: 2035 | I1: 2040 | J1: 2045 | K1: 2050 | L1: 2055 | M1: 2060 | N1: 2065 | O1: 2070
A2: AN | B2: resid rural | C2: 238 | D2: 233.403 | E2: 228 | F2: 222.167 | G2: 214.61 | H2: 207.748 | I2: 197.283 | J2: 194.873 | K2: 192.794 | L2: 189.318 | M2: 184.524 | N2: 177.758 | O2: 169.916
A3: AN | B3: resid urban | C3: 143 | D3: 157.597 | E3: 172 | F3: 187.833 | G3: 204.39 | H3: 221.252 | I3: 240.717 | J3: 253.127 | K3: 267.206 | L3: 280.682 | M3: 293.476 | N3: 304.242 | O3: 314.084
A4: AP | B4: resid rural | C4: 34967 | D4: 34762 | E4: 34169 | F4: 33136 | G4: 31739.4 | H4: 30113.2 | I4: 28480.9 | J4: 26912.8 | K4: 25746.6 | L4: 24519.6 | M4: 23734 | N4: 22840.3 | O4: 21853
A5: AP | B5: resid urban | C5: 14610 | D5: 16609 | E5: 18618 | F5: 20573 | G5: 22475.6 | H5: 24379.8 | I5: 26290.1 | J5: 28011.2 | K5: 29033.4 | L5: 29968.4 | M5: 30207 | N5: 30276.7 | O5: 30178
A6: AR | B6: resid rural | C6: 1067 | D6: 1108 | E6: 1147 | F6: 1182 | G6: 1211 | H6: 1239.43 | I6: 1263.35 | J6: 1305.44 | K6: 1338.65 | L6: 1352.72 | M6: 1356.2 | N6: 1353.34 | O6: 1342.87
A7: AR | B7: resid urban | C7: 317 | D7: 351 | E7: 386 | F7: 422 | G7: 458 | H7: 495.57 | I7: 537.645 | J7: 564.561 | K7: 588.354 | L7: 604.275 | M7: 615.798 | N7: 624.662 | O7: 630.134
A8: AS | B8: resid rural | C8: 26807 | D8: 28289 | E8: 29675 | F8: 30869 | G8: 31878 | H8: 32637 | I8: 32734.6 | J8: 32575.1 | K8: 32208.2 | L8: 31765.3 | M8: 31177.3 | N8: 30427.6 | O8: 29528.1
A9: AS | B9: resid urban | C9: 4399 | D9: 4879 | E9: 5368 | F9: 5848 | G9: 6318 | H9: 6762 | I9: 7638.4 | J9: 8490.92 | K9: 9314.85 | L9: 10135.7 | M9: 10923.7 | N9: 11659.4 | O9: 12331.9
A10: BR | B10: resid rural | C10: 92341 | D10: 100801 | E10: 108166 | F10: 115711 | G10: 122842 | H10: 128835 | I10: 132243 | J10: 134195 | K10: 135266 | L10: 134397 | M10: 132719 | N10: 129530 | O10: 125696
A11: BR | B11: resid urban | C11: 11758 | D11: 13375 | E11: 14917 | F11: 16554 | G11: 18199 | H11: 19741 | I11: 21527.9 | J11: 23681.5 | K11: 25765 | L11: 28508.4 | M11: 31131.7 | N11: 34432 | O11: 37545.7
A12: CG | B12: resid rural | C12: 19608 | D12: 20713 | E12: 21683 | F12: 22448 | G12: 23011 | H12: 23421 | I12: 23341.8 | J12: 23564.3 | K12: 23641.1 | L12: 23649.6 | M12: 23547.3 | N12: 23322.2 | O12: 22976.6
... A75: WB | B75: resid urban | C75: 29093 | D75: 32232 | E75: 35280 | F75: 38247 | G75: 41068 | H75: 43658 | I75: 46374.1 | J75: 47191.3 | K75: 47772.2 | L75: 48158.3 | M75: 48288.6 | N75: 48148.7 | O75: 47742.2

Sheet FinalHHSize
A1: region | B1: Consumer | C1: 2010 | D1: 2015 | E1: 2020 | F1: 2025 | G1: 2030 | H1: 2035 | I1: 2040 | J1: 2045 | K1: 2050 | L1: 2055 | M1: 2060 | N1: 2065 | O1: 2070 | Q1: HH Size | R1: States | S1: Consumer | T1: 2010 | U1: 2015 | V1: 2020 | W1: 2025 | X1: 2030 | Y1: 2035 | Z1: 2040 | AA1: 2045 | AB1: 2050 | AC1: 2055 | AD1: 2060 | AE1: 2065 | AF1: 2070
A2: AN | B2: resid rural | C2: 238 | D2: 233.403 | E2: 228 | F2: 222.167 | G2: 214.61 | H2: 207.748 | I2: 197.283 | J2: 194.873 | K2: 192.794 | L2: 189.318 | M2: 184.524 | N2: 177.758 | O2: 169.916 | R2: AN | S2: resid rural | T2: =(C2*1000)/'Household Size'!$B$3 -> 44905.66 | U2: =(D2*1000)/'Household Size'!$C$3 -> 44885.192 | V2: =(E2*1000)/'Household Size'!$D$3 -> 44705.882 | W2: =(F2*1000)/'Household Size'!$E$3 -> 45340.204 | X2: =(G2*1000)/'Household Size'!$F$3 -> 44710.417 | Y2: =(H2*1000)/'Household Size'!$G$3 -> 44201.702 | Z2: =(I2*1000)/'Household Size'!$H$3 -> 42887.609 | AA2: =(J2*1000)/'Household Size'!$I$3 -> 44289.318 | AB2: =(K2*1000)/'Household Size'!$J$3 -> 44835.814 | AC2: =(L2*1000)/'Household Size'!$K$3 -> 45075.714 | AD2: =(M2*1000)/'Household Size'!$L$3 -> 45005.854 | AE2: =(N2*1000)/'Household Size'!$M$3 -> 44439.5 | AF2: =(O2*1000)/'Household Size'!$N$3 -> 44714.737
A3: AP | B3: resid rural | C3: 34967 | D3: 34762 | E3: 34169 | F3: 33136 | G3: 31739.4 | H3: 30113.2 | I3: 28480.9 | J3: 26912.8 | K3: 25746.6 | L3: 24519.6 | M3: 23734 | N3: 22840.3 | O3: 21853 | R3: AP | S3: resid rural | T3: =(C3*1000)/'Household Size'!$B$3 -> 6597547.2 | U3: =(D3*1000)/'Household Size'!$C$3 -> 6685000 | V3: =(E3*1000)/'Household Size'!$D$3 -> 6699803.9 | W3: =(F3*1000)/'Household Size'!$E$3 -> 6762449 | X3: =(G3*1000)/'Household Size'!$F$3 -> 6612375 | Y3: =(H3*1000)/'Household Size'!$G$3 -> 6407063.8 | Z3: =(I3*1000)/'Household Size'!$H$3 -> 6191500 | AA3: =(J3*1000)/'Household Size'!$I$3 -> 6116545.5 | AB3: =(K3*1000)/'Household Size'!$J$3 -> 5987581.4 | AC3: =(L3*1000)/'Household Size'!$K$3 -> 5838000 | AD3: =(M3*1000)/'Household Size'!$L$3 -> 5788780.5 | AE3: =(N3*1000)/'Household Size'!$M$3 -> 5710075 | AF3: =(O3*1000)/'Household Size'!$N$3 -> 5750789.5
A4: AR | B4: resid rural | C4: 1067 | D4: 1108 | E4: 1147 | F4: 1182 | G4: 1211 | H4: 1239.43 | I4: 1263.35 | J4: 1305.44 | K4: 1338.65 | L4: 1352.72 | M4: 1356.2 | N4: 1353.34 | O4: 1342.87 | R4: AR | S4: resid rural | T4: =(C4*1000)/'Household Size'!$B$3 -> 201320.75 | U4: =(D4*1000)/'Household Size'!$C$3 -> 213076.92 | V4: =(E4*1000)/'Household Size'!$D$3 -> 224901.96 | W4: =(F4*1000)/'Household Size'!$E$3 -> 241224.49 | X4: =(G4*1000)/'Household Size'!$F$3 -> 252291.67 | Y4: =(H4*1000)/'Household Size'!$G$3 -> 263708.51 | Z4: =(I4*1000)/'Household Size'!$H$3 -> 274641.3 | AA4: =(J4*1000)/'Household Size'!$I$3 -> 296690.91 | AB4: =(K4*1000)/'Household Size'!$J$3 -> 311313.95 | AC4: =(L4*1000)/'Household Size'!$K$3 -> 322076.19 | AD4: =(M4*1000)/'Household Size'!$L$3 -> 330780.49 | AE4: =(N4*1000)/'Household Size'!$M$3 -> 338335 | AF4: =(O4*1000)/'Household Size'!$N$3 -> 353386.84
A5: AS | B5: resid rural | C5: 26807 | D5: 28289 | E5: 29675 | F5: 30869 | G5: 31878 | H5: 32637 | I5: 32734.6 | J5: 32575.1 | K5: 32208.2 | L5: 31765.3 | M5: 31177.3 | N5: 30427.6 | O5: 29528.1 | R5: AS | S5: resid rural | T5: =(C5*1000)/'Household Size'!$B$3 -> 5057924.5 | U5: =(D5*1000)/'Household Size'!$C$3 -> 5440192.3 | V5: =(E5*1000)/'Household Size'!$D$3 -> 5818627.5 | W5: =(F5*1000)/'Household Size'!$E$3 -> 6299795.9 | X5: =(G5*1000)/'Household Size'!$F$3 -> 6641250 | Y5: =(H5*1000)/'Household Size'!$G$3 -> 6944042.6 | Z5: =(I5*1000)/'Household Size'!$H$3 -> 7116217.4 | AA5: =(J5*1000)/'Household Size'!$I$3 -> 7403431.8 | AB5: =(K5*1000)/'Household Size'!$J$3 -> 7490279.1 | AC5: =(L5*1000)/'Household Size'!$K$3 -> 7563166.7 | AD5: =(M5*1000)/'Household Size'!$L$3 -> 7604219.5 | AE5: =(N5*1000)/'Household Size'!$M$3 -> 7606900 | AF5: =(O5*1000)/'Household Size'!$N$3 -> 7770552.6
A6: BR | B6: resid rural | C6: 92341 | D6: 100801 | E6: 108166 | F6: 115711 | G6: 122842 | H6: 128835 | I6: 132243 | J6: 134195 | K6: 135266 | L6: 134397 | M6: 132719 | N6: 129530 | O6: 125696 | R6: BR | S6: resid rural | T6: =(C6*1000)/'Household Size'!$B$3 -> 17422830 | U6: =(D6*1000)/'Household Size'!$C$3 -> 19384808 | V6: =(E6*1000)/'Household Size'!$D$3 -> 21209020 | W6: =(F6*1000)/'Household Size'!$E$3 -> 23614490 | X6: =(G6*1000)/'Household Size'!$F$3 -> 25592083 | Y6: =(H6*1000)/'Household Size'!$G$3 -> 27411702 | Z6: =(I6*1000)/'Household Size'!$H$3 -> 28748478 | AA6: =(J6*1000)/'Household Size'!$I$3 -> 30498864 | AB6: =(K6*1000)/'Household Size'!$J$3 -> 31457209 | AC6: =(L6*1000)/'Household Size'!$K$3 -> 31999286 | AD6: =(M6*1000)/'Household Size'!$L$3 -> 32370488 | AE6: =(N6*1000)/'Household Size'!$M$3 -> 32382500 | AF6: =(O6*1000)/'Household Size'!$N$3 -> 33077895
A7: CG | B7: resid rural | C7: 19608 | D7: 20713 | E7: 21683 | F7: 22448 | G7: 23011 | H7: 23421 | I7: 23341.8 | J7: 23564.3 | K7: 23641.1 | L7: 23649.6 | M7: 23547.3 | N7: 23322.2 | O7: 22976.6 | R7: CG | S7: resid rural | T7: =(C7*1000)/'Household Size'!$B$3 -> 3699622.6 | U7: =(D7*1000)/'Household Size'!$C$3 -> 3983269.2 | V7: =(E7*1000)/'Household Size'!$D$3 -> 4251568.6 | W7: =(F7*1000)/'Household Size'!$E$3 -> 4581224.5 | X7: =(G7*1000)/'Household Size'!$F$3 -> 4793958.3 | Y7: =(H7*1000)/'Household Size'!$G$3 -> 4983191.5 | Z7: =(I7*1000)/'Household Size'!$H$3 -> 5074304.3 | AA7: =(J7*1000)/'Household Size'!$I$3 -> 5355522.7 | AB7: =(K7*1000)/'Household Size'!$J$3 -> 5497930.2 | AC7: =(L7*1000)/'Household Size'!$K$3 -> 5630857.1 | AD7: =(M7*1000)/'Household Size'!$L$3 -> 5743243.9 | AE7: =(N7*1000)/'Household Size'!$M$3 -> 5830550 | AF7: =(O7*1000)/'Household Size'!$N$3 -> 6046473.7
A8: CH | B8: resid rural | C8: 29 | D8: 13 | E8: 12.08 | F8: 12.67 | G8: 13.31 | H8: 13.96 | I8: 14.6 | J8: 15.49 | K8: 16.26 | L8: 16.87 | M8: 17.36 | N8: 17.77 | O8: 18.09 | R8: CH | S8: resid rural | T8: =(C8*1000)/'Household Size'!$B$3 -> 5471.6981 | U8: =(D8*1000)/'Household Size'!$C$3 -> 2500 | V8: =(E8*1000)/'Household Size'!$D$3 -> 2368.6275 | W8: =(F8*1000)/'Household Size'!$E$3 -> 2585.7143 | X8: =(G8*1000)/'Household Size'!$F$3 -> 2772.9167 | Y8: =(H8*1000)/'Household Size'!$G$3 -> 2970.2128 | Z8: =(I8*1000)/'Household Size'!$H$3 -> 3173.913 | AA8: =(J8*1000)/'Household Size'!$I$3 -> 3520.4545 | AB8: =(K8*1000)/'Household Size'!$J$3 -> 3781.3953 | AC8: =(L8*1000)/'Household Size'!$K$3 -> 4016.6667 | AD8: =(M8*1000)/'Household Size'!$L$3 -> 4234.1463 | AE8: =(N8*1000)/'Household Size'!$M$3 -> 4442.5 | AF8: =(O8*1000)/'Household Size'!$N$3 -> 4760.5263
A9: DD | B9: resid rural | C9: 60 | D9: 42 | E9: 28 | F9: 19 | G9: 14.1293 | H9: 10.2174 | I9: 18.03 | J9: 21.69 | K9: 24.1 | L9: 26.52 | M9: 27.51 | N9: 28.36 | O9: 29.06 | R9: DD | S9: resid rural | T9: =(C9*1000)/'Household Size'!$B$3 -> 11320.755 | U9: =(D9*1000)/'Household Size'!$C$3 -> 8076.9231 | V9: =(E9*1000)/'Household Size'!$D$3 -> 5490.1961 | W9: =(F9*1000)/'Household Size'!$E$3 -> 3877.551 | X9: =(G9*1000)/'Household Size'!$F$3 -> 2943.6042 | Y9: =(H9*1000)/'Household Size'!$G$3 -> 2173.9149 | Z9: =(I9*1000)/'Household Size'!$H$3 -> 3919.5652 | AA9: =(J9*1000)/'Household Size'!$I$3 -> 4929.5455 | AB9: =(K9*1000)/'Household Size'!$J$3 -> 5604.6512 | AC9: =(L9*1000)/'Household Size'!$K$3 -> 6314.2857 | AD9: =(M9*1000)/'Household Size'!$L$3 -> 6709.7561 | AE9: =(N9*1000)/'Household Size'!$M$3 -> 7090 | AF9: =(O9*1000)/'Household Size'!$N$3 -> 7647.3684
A10: DL | B10: resid rural | C10: 419 | D10: 260 | E10: 133 | F10: 225.4 | G10: 245.52 | H10: 265.91 | I10: 285.24 | J10: 302.39 | K10: 317.47 | L10: 330.38 | M10: 341.65 | N10: 351.2 | O10: 358.91 | R10: DL | S10: resid rural | T10: =(C10*1000)/'Household Size'!$B$3 -> 79056.604 | U10: =(D10*1000)/'Household Size'!$C$3 -> 50000 | V10: =(E10*1000)/'Household Size'!$D$3 -> 26078.431 | W10: =(F10*1000)/'Household Size'!$E$3 -> 46000 | X10: =(G10*1000)/'Household Size'!$F$3 -> 51150 | Y10: =(H10*1000)/'Household Size'!$G$3 -> 56576.596 | Z10: =(I10*1000)/'Household Size'!$H$3 -> 62008.696 | AA10: =(J10*1000)/'Household Size'!$I$3 -> 68725 | AB10: =(K10*1000)/'Household Size'!$J$3 -> 73830.233 | AC10: =(L10*1000)/'Household Size'!$K$3 -> 78661.905 | AD10: =(M10*1000)/'Household Size'!$L$3 -> 83329.268 | AE10: =(N10*1000)/'Household Size'!$M$3 -> 87800 | AF10: =(O10*1000)/'Household Size'!$N$3 -> 94450
A11: DN | B11: resid rural | C11: 183 | D11: 188 | E11: 200 | F11: 223 | G11: 262 | H11: 293.84 | I11: 282.24 | J11: 273.14 | K11: 256.44 | L11: 223.1 | M11: 207.45 | N11: 213.3 | O11: 218.07 | R11: DN | S11: resid rural | T11: =(C11*1000)/'Household Size'!$B$3 -> 34528.302 | U11: =(D11*1000)/'Household Size'!$C$3 -> 36153.846 | V11: =(E11*1000)/'Household Size'!$D$3 -> 39215.686 | W11: =(F11*1000)/'Household Size'!$E$3 -> 45510.204 | X11: =(G11*1000)/'Household Size'!$F$3 -> 54583.333 | Y11: =(H11*1000)/'Household Size'!$G$3 -> 62519.149 | Z11: =(I11*1000)/'Household Size'!$H$3 -> 61356.522 | AA11: =(J11*1000)/'Household Size'!$I$3 -> 62077.273 | AB11: =(K11*1000)/'Household Size'!$J$3 -> 59637.209 | AC11: =(L11*1000)/'Household Size'!$K$3 -> 53119.048 | AD11: =(M11*1000)/'Household Size'!$L$3 -> 50597.561 | AE11: =(N11*1000)/'Household Size'!$M$3 -> 53325 | AF11: =(O11*1000)/'Household Size'!$N$3 -> 57386.842
A12: GA | B12: resid rural | C12: 552 | D12: 483 | E12: 411 | F12: 337 | G12: 264 | H12: 198.004 | I12: 181.335 | J12: 177.8 | K12: 163.71 | L12: 147.76 | M12: 149.28 | N12: 150.08 | O12: 150 | R12: GA | S12: resid rural | T12: =(C12*1000)/'Household Size'!$B$3 -> 104150.94 | U12: =(D12*1000)/'Household Size'!$C$3 -> 92884.615 | V12: =(E12*1000)/'Household Size'!$D$3 -> 80588.235 | W12: =(F12*1000)/'Household Size'!$E$3 -> 68775.51 | X12: =(G12*1000)/'Household Size'!$F$3 -> 55000 | Y12: =(H12*1000)/'Household Size'!$G$3 -> 42128.511 | Z12: =(I12*1000)/'Household Size'!$H$3 -> 39420.652 | AA12: =(J12*1000)/'Household Size'!$I$3 -> 40409.091 | AB12: =(K12*1000)/'Household Size'!$J$3 -> 38072.093 | AC12: =(L12*1000)/'Household Size'!$K$3 -> 35180.952 | AD12: =(M12*1000)/'Household Size'!$L$3 -> 36409.756 | AE12: =(N12*1000)/'Household Size'!$M$3 -> 37520 | AF12: =(O12*1000)/'Household Size'!$N$3 -> 39473.684
A13: GJ | B13: resid rural | C13: 34695 | D13: 35701 | E13: 36473 | F13: 36894 | G13: 36929 | H13: 36599 | I13: 35158.1 | J13: 34596.6 | K13: 33765.4 | L13: 32693 | M13: 31408 | N13: 29931.8 | O13: 28287.5 | R13: GJ | S13: resid rural | T13: =(C13*1000)/'Household Size'!$B$3 -> 6546226.4 | U13: =(D13*1000)/'Household Size'!$C$3 -> 6865576.9 | V13: =(E13*1000)/'Household Size'!$D$3 -> 7151568.6 | W13: =(F13*1000)/'Household Size'!$E$3 -> 7529387.8 | X13: =(G13*1000)/'Household Size'!$F$3 -> 7693541.7 | Y13: =(H13*1000)/'Household Size'!$G$3 -> 7787021.3 | Z13: =(I13*1000)/'Household Size'!$H$3 -> 7643065.2 | AA13: =(J13*1000)/'Household Size'!$I$3 -> 7862863.6 | AB13: =(K13*1000)/'Household Size'!$J$3 -> 7852418.6 | AC13: =(L13*1000)/'Household Size'!$K$3 -> 7784047.6 | AD13: =(M13*1000)/'Household Size'!$L$3 -> 7660487.8 | AE13: =(N13*1000)/'Household Size'!$M$3 -> 7482950 | AF13: =(O13*1000)/'Household Size'!$N$3 -> 7444078.9
... A38: WB | B38: resid rural | C38: 62183 | D38: 62847 | E38: 62845 | F38: 62275 | G38: 61099 | H38: 59273 | I38: 56887.9 | J38: 55720.7 | K38: 54255.8 | L38: 52570.7 | M38: 50627.4 | N38: 48444.3 | O38: 46057.8 | R38: WB | S38: resid rural | T38: =(C38*1000)/'Household Size'!$B$3 -> 11732642 | U38: =(D38*1000)/'Household Size'!$C$3 -> 12085962 | V38: =(E38*1000)/'Household Size'!$D$3 -> 12322549 | W38: =(F38*1000)/'Household Size'!$E$3 -> 12709184 | X38: =(G38*1000)/'Household Size'!$F$3 -> 12728958 | Y38: =(H38*1000)/'Household Size'!$G$3 -> 12611277 | Z38: =(I38*1000)/'Household Size'!$H$3 -> 12366935 | AA38: =(J38*1000)/'Household Size'!$I$3 -> 12663795 | AB38: =(K38*1000)/'Household Size'!$J$3 -> 12617628 | AC38: =(L38*1000)/'Household Size'!$K$3 -> 12516833 | AD38: =(M38*1000)/'Household Size'!$L$3 -> 12348146 | AE38: =(N38*1000)/'Household Size'!$M$3 -> 12111075 | AF38: =(O38*1000)/'Household Size'!$N$3 -> 12120474
A39: AN | B39: resid urban | C39: 143 | D39: 157.597 | E39: 172 | F39: 187.833 | G39: 204.39 | H39: 221.252 | I39: 240.717 | J39: 253.127 | K39: 267.206 | L39: 280.682 | M39: 293.476 | N39: 304.242 | O39: 314.084 | R39: AN | S39: resid urban | T39: =(C39*1000)/'Household Size'!$B$4 -> 25535.714 | U39: =(D39*1000)/'Household Size'!$C$4 -> 29184.63 | V39: =(E39*1000)/'Household Size'!$D$4 -> 32452.83 | W39: =(F39*1000)/'Household Size'!$E$4 -> 36830 | X39: =(G39*1000)/'Household Size'!$F$4 -> 40878 | Y39: =(H39*1000)/'Household Size'!$G$4 -> 46094.167 | Z39: =(I39*1000)/'Household Size'!$H$4 -> 52329.783 | AA39: =(J39*1000)/'Household Size'!$I$4 -> 56250.444 | AB39: =(K39*1000)/'Household Size'!$J$4 -> 62140.93 | AC39: =(L39*1000)/'Household Size'!$K$4 -> 66829.048 | AD39: =(M39*1000)/'Household Size'!$L$4 -> 73369 | AE39: =(N39*1000)/'Household Size'!$M$4 -> 80063.684 | AF39: =(O39*1000)/'Household Size'!$N$4 -> 84887.568
A40: AP | B40: resid urban | C40: 14610 | D40: 16609 | E40: 18618 | F40: 20573 | G40: 22475.6 | H40: 24379.8 | I40: 26290.1 | J40: 28011.2 | K40: 29033.4 | L40: 29968.4 | M40: 30207 | N40: 30276.7 | O40: 30178 | R40: AP | S40: resid urban | T40: =(C40*1000)/'Household Size'!$B$4 -> 2608928.6 | U40: =(D40*1000)/'Household Size'!$C$4 -> 3075740.7 | V40: =(E40*1000)/'Household Size'!$D$4 -> 3512830.2 | W40: =(F40*1000)/'Household Size'!$E$4 -> 4033921.6 | X40: =(G40*1000)/'Household Size'!$F$4 -> 4495120 | Y40: =(H40*1000)/'Household Size'!$G$4 -> 5079125 | Z40: =(I40*1000)/'Household Size'!$H$4 -> 5715239.1 | AA40: =(J40*1000)/'Household Size'!$I$4 -> 6224711.1 | AB40: =(K40*1000)/'Household Size'!$J$4 -> 6751953.5 | AC40: =(L40*1000)/'Household Size'!$K$4 -> 7135333.3 | AD40: =(M40*1000)/'Household Size'!$L$4 -> 7551750 | AE40: =(N40*1000)/'Household Size'!$M$4 -> 7967552.6 | AF40: =(O40*1000)/'Household Size'!$N$4 -> 8156216.2
A41: AR | B41: resid urban | C41: 317 | D41: 351 | E41: 386 | F41: 422 | G41: 458 | H41: 495.57 | I41: 537.645 | J41: 564.561 | K41: 588.354 | L41: 604.275 | M41: 615.798 | N41: 624.662 | O41: 630.134 | R41: AR | S41: resid urban | T41: =(C41*1000)/'Household Size'!$B$4 -> 56607.143 | U41: =(D41*1000)/'Household Size'!$C$4 -> 65000 | V41: =(E41*1000)/'Household Size'!$D$4 -> 72830.189 | W41: =(F41*1000)/'Household Size'!$E$4 -> 82745.098 | X41: =(G41*1000)/'Household Size'!$F$4 -> 91600 | Y41: =(H41*1000)/'Household Size'!$G$4 -> 103243.75 | Z41: =(I41*1000)/'Household Size'!$H$4 -> 116879.35 | AA41: =(J41*1000)/'Household Size'!$I$4 -> 125458 | AB41: =(K41*1000)/'Household Size'!$J$4 -> 136826.51 | AC41: =(L41*1000)/'Household Size'!$K$4 -> 143875 | AD41: =(M41*1000)/'Household Size'!$L$4 -> 153949.5 | AE41: =(N41*1000)/'Household Size'!$M$4 -> 164384.74 | AF41: =(O41*1000)/'Household Size'!$N$4 -> 170306.49
A42: AS | B42: resid urban | C42: 4399 | D42: 4879 | E42: 5368 | F42: 5848 | G42: 6318 | H42: 6762 | I42: 7638.4 | J42: 8490.92 | K42: 9314.85 | L42: 10135.7 | M42: 10923.7 | N42: 11659.4 | O42: 12331.9 | R42: AS | S42: resid urban | T42: =(C42*1000)/'Household Size'!$B$4 -> 785535.71 | U42: =(D42*1000)/'Household Size'!$C$4 -> 903518.52 | V42: =(E42*1000)/'Household Size'!$D$4 -> 1012830.2 | W42: =(F42*1000)/'Household Size'!$E$4 -> 1146666.7 | X42: =(G42*1000)/'Household Size'!$F$4 -> 1263600 | Y42: =(H42*1000)/'Household Size'!$G$4 -> 1408750 | Z42: =(I42*1000)/'Household Size'!$H$4 -> 1660521.7 | AA42: =(J42*1000)/'Household Size'!$I$4 -> 1886871.1 | AB42: =(K42*1000)/'Household Size'!$J$4 -> 2166244.2 | AC42: =(L42*1000)/'Household Size'!$K$4 -> 2413261.9 | AD42: =(M42*1000)/'Household Size'!$L$4 -> 2730925 | AE42: =(N42*1000)/'Household Size'!$M$4 -> 3068263.2 | AF42: =(O42*1000)/'Household Size'!$N$4 -> 3332945.9
A43: BR | B43: resid urban | C43: 11758 | D43: 13375 | E43: 14917 | F43: 16554 | G43: 18199 | H43: 19741 | I43: 21527.9 | J43: 23681.5 | K43: 25765 | L43: 28508.4 | M43: 31131.7 | N43: 34432 | O43: 37545.7 | R43: BR | S43: resid urban | T43: =(C43*1000)/'Household Size'!$B$4 -> 2099642.9 | U43: =(D43*1000)/'Household Size'!$C$4 -> 2476851.9 | V43: =(E43*1000)/'Household Size'!$D$4 -> 2814528.3 | W43: =(F43*1000)/'Household Size'!$E$4 -> 3245882.4 | X43: =(G43*1000)/'Household Size'!$F$4 -> 3639800 | Y43: =(H43*1000)/'Household Size'!$G$4 -> 4112708.3 | Z43: =(I43*1000)/'Household Size'!$H$4 -> 4679978.3 | AA43: =(J43*1000)/'Household Size'!$I$4 -> 5262555.6 | AB43: =(K43*1000)/'Household Size'!$J$4 -> 5991860.5 | AC43: =(L43*1000)/'Household Size'!$K$4 -> 6787714.3 | AD43: =(M43*1000)/'Household Size'!$L$4 -> 7782925 | AE43: =(N43*1000)/'Household Size'!$M$4 -> 9061052.6 | AF43: =(O43*1000)/'Household Size'!$N$4 -> 10147486
